Workbook
Name PESO_EXAMEN: Configuración!$C$26
Name PESO_PRACTICA: Configuración!$C$27

Sheet Inicio
B2: EvalFP — Cuaderno del Profesor
B3: Motor de Evaluación Relacional para Formación Profesional · v2.0
B5: 🏠 Inicio | C5: =HYPERLINK("#Configuración!A1","⚙️ Config") -> ⚙️ Config | D5: =HYPERLINK("#Mis Módulos!A1","📚 Módulos") -> 📚 Módulos | E5: =HYPERLINK("#Biblioteca!A1","📖 Biblioteca") -> 📖 Biblioteca | F5: =HYPERLINK("#Calendario!A1","📅 Calendario") -> 📅 Calendario | G5: =HYPERLINK("#Hoy!A1","☀️ Hoy") -> ☀️ Hoy | H5: =HYPERLINK("#Dashboard Global!A1","📊 Dashboard+") -> 📊 Dashboard+
B8: 📌 Información del Módulo
B9: Módulo | C9: Implantación de Sistemas Operativos (ISO)
B10: Código | C10: 0369
B11: Ciclo | C11: Administración de Sistemas Informáticos en Red (ASIR)
B12: Curso | C12: 1º ASIR
B13: Año académico | C13: 2026-2027
B14: Horas semanales | C14: 6 h/sem
B15: Total horas | C15: 186 h
B16: Evaluaciones | C16: 3 evaluaciones
B18: 📊 Ponderación de Resultados de Aprendizaje
B19: RA | C19: Resultado de Aprendizaje | D19: Pond. % | E19: Horas equiv. | F19: CEs
B20: RA1 | C20: Instala sistemas operativos, relacionando sus características con el hardware de | D20: 13% | E20: 24.0 h | F20: 8
B21: RA2 | C21: Gestiona el software de base, aplicando criterios de explotación del sistema. | D21: 19% | E21: 35.3 h | F21: 19
B22: RA3 | C22: Asegura y recupera el sistema, aplicando procedimientos de administración de la | D22: 9% | E22: 16.0 h | F22: 8
B23: RA4 | C23: Gestiona dominios, elaborando el modelo lógico de la red en un entorno de trabaj | D23: 16% | E23: 30.0 h | F23: 8
B24: RA5 | C24: Administra el acceso al dominio, gestionando servidores de directorio y verifica | D24: 13% | E24: 24.1 h | F24: 8
B25: RA6 | C25: Supervisa el rendimiento del sistema, diagnosticando las causas de pérdidas de r | D25: 12% | E25: 22.0 h | F25: 10
B26: RA7 | C26: Aplica directivas de seguridad y gestiona auditorías, interpretando y aplicando | D26: 13% | E26: 24.6 h | F26: 9
B27: RA8 | C27: Establece la conexión en red de los sistemas informáticos, configurando disposit | D27: 5% | E27: 10.0 h | F27: 9
B29: 📅 Unidades de Trabajo por Evaluación
B30: UT | C30: Título | D30: Horas | E30: % Total | F30: Evaluación
B31: UT1 | C31: Instalación de software libre y propietario | D31: 30h | E31: 16.1% | F31: Evaluación 1
B32: UT2 | C32: Administración de software base | D32: 25h | E32: 13.4% | F32: Evaluación 1
B33: UT3 | C33: Administración y aseguramiento de la información | D33: 22h | E33: 11.8% | F33: Evaluación 2
B34: UT4 | C34: Gestión de dominios | D34: 30h | E34: 16.1% | F34: Evaluación 2
B35: UT5 | C35: Administración de acceso al dominio | D35: 25h | E35: 13.4% | F35: Evaluación 2
B36: UT6 | C36: Supervisión del rendimiento del sistema | D36: 22h | E36: 11.8% | F36: Evaluación 3
B37: UT7 | C37: Directivas de seguridad y auditorías | D37: 22h | E37: 11.8% | F37: Evaluación 3
B38: UT8 | C38: Resolución de incidencias y asistencia técnica | D38: 10h | E38: 5.4% | F38: Evaluación 3
B39: TOTAL | D39: 186h | E39: 100%

Sheet Mis Módulos
B2: 📚 Mis Módulos — Carga Docente
B3: Módulos y grupos gestionados en este cuaderno · EvalFP 2.0
B5: =HYPERLINK("#Inicio!A1","🏠 Inicio") -> 🏠 Inicio | C5: =HYPERLINK("#Configuración!A1","⚙️ Config") -> ⚙️ Config | D5: 📚 Módulos | E5: =HYPERLINK("#Biblioteca!A1","📖 Biblioteca") -> 📖 Biblioteca | F5: =HYPERLINK("#Calendario!A1","📅 Calendario") -> 📅 Calendario | G5: =HYPERLINK("#Hoy!A1","☀️ Hoy") -> ☀️ Hoy | H5: =HYPERLINK("#Dashboard Global!A1","📊 Dashboard+") -> 📊 Dashboard+
B8: MÓDULOS ACTIVOS — haz clic en el nombre para ir al módulo
B9: Abrev. | C9: Módulo | D9: Grupo | E9: Horas | F9: RAs | G9: Evals | H9: Ir al Inicio | I9: Ir al Dashboard
B10: ISO | C10: Implantación de Sistemas Operativos | D10: 1º ASIR-A | E10: 186 h | F10: 8 | G10: 3 | H10: =HYPERLINK("#ISO · Programación!A1","→ Programación") -> → Programación | I10: =HYPERLINK("#ISO · Dashboard!A1","→ Dashboard") -> → Dashboard
B11: PAR | C11: Planificación y Administración de Redes | D11: 1º ASIR-A | E11: 155 h | F11: 6 | G11: 3 | H11: =HYPERLINK("#PAR · Programación!A1","→ Programación") -> → Programación | I11: =HYPERLINK("#PAR · Dashboard!A1","→ Dashboard") -> → Dashboard
B13: ★ Para añadir un módulo, edita TEACHER_MODULES en scripts/teacher_config.py y regenera el libro.

Sheet Configuración
B2: ⚙️ Configuración
B3: Ajustes del curso, motor de evaluación y preferencias del sistema
B5: =HYPERLINK("#Inicio!A1","🏠 Inicio") -> 🏠 Inicio | C5: ⚙️ Config | D5: =HYPERLINK("#Mis Módulos!A1","📚 Módulos") -> 📚 Módulos | E5: =HYPERLINK("#Biblioteca!A1","📖 Biblioteca") -> 📖 Biblioteca | F5: =HYPERLINK("#Calendario!A1","📅 Calendario") -> 📅 Calendario | G5: =HYPERLINK("#Hoy!A1","☀️ Hoy") -> ☀️ Hoy | H5: =HYPERLINK("#Dashboard Global!A1","📊 Dashboard+") -> 📊 Dashboard+
B8: 📚 BLOQUE 1 — Datos del Curso
B9: Nombre del módulo | C9: Implantación de Sistemas Operativos | D9: ✏️ editable
B10: Código módulo | C10: 0369 | D10: ✏️ editable
B11: Ciclo formativo | C11: Administración de Sistemas Informáticos en Red (ASIR) | D11: ✏️ editable
B12: Curso | C12: 1º ASIR | D12: ✏️ editable
B13: Año académico | C13: 2026-2027 | D13: ✏️ editable
B14: Nombre del profesor/a | D14: ✏️ editable
B15: Grupo/s | D15: ✏️ editable
B16: Centro educativo | D16: ✏️ editable
B18: ⚙️ BLOQUE 2 — Motor de Evaluación
B19: N.º de evaluaciones | C19: 3
B20: Nota mínima aprobado | C20: 5 | D20: ✏️ editable
B21: Nota máxima | C21: 10
B22: Redondeo | C22: 0.00 decimales | D22: ✏️ editable
B23: Peso Eval 1 (RA1 13% + RA2 19%) | C23: 32%
B24: Peso Eval 2 (RA3 9% + RA4 16% + RA5 13%) | C24: 38%
B25: Peso Eval 3 (RA6 12% + RA7 13% + RA8 5%) | C25: 30%
B26: Peso examen (teoría) | C26: 0.75
B27: Peso prácticas (actividades) | C27: 0.25
B28: ⚠️ Los dos valores deben sumar 100%. Si los cambias, las notas de Reg. Notas se recalculan automáticamente.
B29: Recuperación | C29: Sí — convocatoria extraordinaria | D29: ✏️ editable
B31: ⚠️ PRÁCTICAS EN EMPRESA (2ª EVALUACIÓN): El alumnado realiza 18h de prácticas en empresa durante la 2ª evaluación (3 semanas × 6h/sem). Estas horas afectan únicamente a la temporalización — hay menos tiempo para impartir UT3, UT4 y UT5 — pero NO modifican las ponderaciones curriculares de los RAs.
B33: 🖨️ BLOQUE 3 — Preferencias del Sistema
B34: Formato boletines | C34: PDF · 1 por alumno/a | D34: ✏️ editable
B35: Ruta exportación PDF | D35: ✏️ editable
B36: Email destino | D36: ✏️ editable
B37: Logo del centro | C37: (no configurado) | D37: ✏️ editable

Sheet Biblioteca
B2: 📖 Biblioteca de Recursos
B3: Actividades · Exámenes · Rúbricas — compartidos entre módulos
B5: =HYPERLINK("#Inicio!A1","🏠 Inicio") -> 🏠 Inicio | C5: =HYPERLINK("#Configuración!A1","⚙️ Config") -> ⚙️ Config | D5: =HYPERLINK("#Mis Módulos!A1","📚 Módulos") -> 📚 Módulos | E5: 📖 Biblioteca | F5: =HYPERLINK("#Calendario!A1","📅 Calendario") -> 📅 Calendario | G5: =HYPERLINK("#Hoy!A1","☀️ Hoy") -> ☀️ Hoy | H5: =HYPERLINK("#Dashboard Global!A1","📊 Dashboard+") -> 📊 Dashboard+
B8: ACTIVIDADES PRÁCTICAS — índice de todos los módulos
B9: ID | C9: Módulo | D9: RA | E9: Descripción | F9: Instrumento | G9: Tags | H9: Eval | I9: Peso | J9: 📖 Apuntes
B10: A001 | C10: ISO | D10: RA1 | E10: Instalación de software libre y propietario — práctica RA1 | F10: 🔧 Práctica | G10: Linux · Windows Server · Virtualización | H10: EV1 | I10: 100% | J10: =HYPERLINK("../apuntes/04-FP/ISO/1-asir/instalacion-de-software-libre-y-propietario/index.html","📖 Ver apunte") -> 📖 Ver apunte
B11: A002 | C11: ISO | D11: RA2 | E11: Instalación de software libre y propietario — práctica RA2 | F11: 🔧 Práctica | G11: Linux · Windows Server · Virtualización | H11: EV1 | I11: 100% | J11: =HYPERLINK("../apuntes/04-FP/ISO/1-asir/instalacion-de-software-libre-y-propietario/index.html","📖 Ver apunte") -> 📖 Ver apunte
B12: A003 | C12: ISO | D12: RA2 | E12: Administración de software base — práctica RA2 | F12: 🔧 Práctica | G12: Usuarios · Red TCP/IP · Registro Windows | H12: EV1 | I12: 100% | J12: =HYPERLINK("../apuntes/04-FP/ISO/1-asir/administracion-de-software-base/index.html","📖 Ver apunte") -> 📖 Ver apunte
B13: A004 | C13: ISO | D13: RA3 | E13: Administración y aseguramiento de la información — práctica RA3 | F13: 🔧 Práctica | G13: Permisos · Backups · RAID | H13: EV2 | I13: 100% | J13: =HYPERLINK("../apuntes/04-FP/ISO/1-asir/administracion-y-aseguramiento-de-la-informacion/index.html","📖 Ver apunte") -> 📖 Ver apunte
B14: A005 | C14: ISO | D14: RA4 | E14: Gestión de dominios — práctica RA4 | F14: 🔧 Práctica | G14: Active Directory · GPO · Perfiles | H14: EV2 | I14: 100% | J14: =HYPERLINK("../apuntes/04-FP/ISO/1-asir/gestion-de-dominios/index.html","📖 Ver apunte") -> 📖 Ver apunte
B15: A006 | C15: ISO | D15: RA5 | E15: Administración de acceso al dominio — práctica RA5 | F15: 🔧 Práctica | G15: Samba · NFS · NTFS / ACLs POSIX | H15: EV2 | I15: 100% | J15: =HYPERLINK("../apuntes/04-FP/ISO/1-asir/administracion-de-acceso-al-dominio/index.html","📖 Ver apunte") -> 📖 Ver apunte
B16: A007 | C16: ISO | D16: RA6 | E16: Supervisión del rendimiento del sistema — práctica RA6 | F16: 🔧 Práctica | G16: top/htop · Perfmon · journalctl | H16: EV3 | I16: 100% | J16: =HYPERLINK("../apuntes/04-FP/ISO/1-asir/supervision-del-rendimiento-del-sistema/index.html","📖 Ver apunte") -> 📖 Ver apunte
B17: A008 | C17: ISO | D17: RA7 | E17: Directivas de seguridad y auditorías — práctica RA7 | F17: 🔧 Práctica | G17: secpol.msc · auditd · fail2ban | H17: EV3 | I17: 100% | J17: =HYPERLINK("../apuntes/04-FP/ISO/1-asir/directivas-de-seguridad-y-auditorias/index.html","📖 Ver apunte") -> 📖 Ver apunte
B18: A009 | C18: ISO | D18: RA8 | E18: Resolución de incidencias y asistencia técnica — práctica RA8 | F18: 🔧 Práctica | G18: WDS/MDT · VPN WireGuard · ITIL | H18: EV3 | I18: 100% | J18: =HYPERLINK("../apuntes/04-FP/ISO/1-asir/resolucion-de-incidencias-y-asistencia-tecnica/index.html","📖 Ver apunte") -> 📖 Ver apunte
B19: EX1 | C19: ISO | D19: RA1, RA2 | E19: Examen Evaluación 1 | F19: 📝 Examen | G19: examen · prueba escrita | H19: EV1 | I19: variable
B20: EX2 | C20: ISO | D20: RA3, RA4, RA5 | E20: Examen Evaluación 2 | F20: 📝 Examen | G20: examen · prueba escrita | H20: EV2 | I20: variable
B21: EX3 | C21: ISO | D21: RA6, RA7, RA8 | E21: Examen Evaluación 3 | F21: 📝 Examen | G21: examen · prueba escrita | H21: EV3 | I21: variable
B22: A001 | C22: PAR | D22: RA1 | E22: Introducción a las redes locales — práctica RA1 | F22: 🔧 Práctica | G22: OSI · TCP/IP · Ethernet | H22: EV1 | I22: 100% | J22: =HYPERLINK("../apuntes/04-FP/PAR/1-asir/introduccion-a-las-redes-locales/index.html","📖 Ver apunte") -> 📖 Ver apunte
B23: A002 | C23: PAR | D23: RA2 | E23: Dispositivos de red y medios de transmisión — práctica RA2 | F23: 🔧 Práctica | G23: Switch · Router · Cableado estructurado | H23: EV1 | I23: 100% | J23: =HYPERLINK("../apuntes/04-FP/PAR/1-asir/dispositivos-de-red-y-medios-de-transmision/index.html","📖 Ver apunte") -> 📖 Ver apunte
B24: A003 | C24: PAR | D24: RA1 | E24: Dispositivos de red y medios de transmisión — práctica RA1 | F24: 🔧 Práctica | G24: Switch · Router · Cableado estructurado | H24: EV1 | I24: 100% | J24: =HYPERLINK("../apuntes/04-FP/PAR/1-asir/dispositivos-de-red-y-medios-de-transmision/index.html","📖 Ver apunte") -> 📖 Ver apunte
B25: A004 | C25: PAR | D25: RA3 | E25: Configuración y administración de conmutadores — práctica RA3 | F25: 🔧 Práctica | G25: VLANs · STP · Port-security | H25: EV2 | I25: 100% | J25: =HYPERLINK("../apuntes/04-FP/PAR/1-asir/configuracion-y-administracion-de-conmutadores/index.html","📖 Ver apunte") -> 📖 Ver apunte
B26: A005 | C26: PAR | D26: RA4 | E26: Configuración y administración de routers — práctica RA4 | F26: 🔧 Práctica | G26: OSPF · RIP · NAT · ACLs | H26: EV2 | I26: 100% | J26: =HYPERLINK("../apuntes/04-FP/PAR/1-asir/configuracion-y-administracion-de-routers/index.html","📖 Ver apunte") -> 📖 Ver apunte
B27: A006 | C27: PAR | D27: RA5 | E27: Configuración de redes inalámbricas — práctica RA5 | F27: 🔧 Práctica | G27: WiFi 6 · WPA3 · RADIUS | H27: EV2 | I27: 100% | J27: =HYPERLINK("../apuntes/04-FP/PAR/1-asir/configuracion-de-redes-inalambricas/index.html","📖 Ver apunte") -> 📖 Ver apunte
B28: A007 | C28: PAR | D28: RA4 | E28: Configuración de redes inalámbricas — práctica RA4 | F28: 🔧 Práctica | G28: WiFi 6 · WPA3 · RADIUS | H28: EV2 | I28: 100% | J28: =HYPERLINK("../apuntes/04-FP/PAR/1-asir/configuracion-de-redes-inalambricas/index.html","📖 Ver apunte") -> 📖 Ver apunte
B29: A008 | C29: PAR | D29: RA6 | E29: Resolución de incidencias de red — práctica RA6 | F29: 🔧 Práctica | G29: Wireshark · ping · traceroute · SNMP | H29: EV3 | I29: 100% | J29: =HYPERLINK("../apuntes/04-FP/PAR/1-asir/resolucion-de-incidencias-de-red/index.html","📖 Ver apunte") -> 📖 Ver apunte
B30: EX1 | C30: PAR | D30: RA1, RA2 | E30: Examen Evaluación 1 | F30: 📝 Examen | G30: examen · prueba escrita | H30: EV1 | I30: variable
B31: EX2 | C31: PAR | D31: RA3, RA4, RA5 | E31: Examen Evaluación 2 | F31: 📝 Examen | G31: examen · prueba escrita | H31: EV2 | I31: variable
B32: EX3 | C32: PAR | D32: RA6 | E32: Examen Evaluación 3 | F32: 📝 Examen | G32: examen · prueba escrita | H32: EV3 | I32: variable
B34: INSTRUCCIONES DE USO
B35: • CU13 Buscar actividad: usa Ctrl+F en Excel para buscar por módulo, RA o tag.
B36: • CU12 Duplicar actividad: copia la fila y pégala en la hoja Actividades del módulo destino.
B37: • CU14 Crear rúbrica: ve a la hoja '{ABREV} · Rúbricas' del módulo correspondiente.
B38: • CU05 Crear actividad: añade una fila en esta tabla y en la hoja Actividades del módulo.
B39: • 📖 Apuntes: haz clic en 'Ver apunte' para abrir el HTML de la UT en el navegador.
B40: • Para añadir un nuevo módulo edita teacher_config.py y regenera el libro.

Sheet Calendario
B2: 📅 Calendario Académico
B3: Exámenes · Entregas · Recuperaciones — Curso 2026-2027
B5: =HYPERLINK("#Inicio!A1","🏠 Inicio") -> 🏠 Inicio | C5: =HYPERLINK("#Configuración!A1","⚙️ Config") -> ⚙️ Config | D5: =HYPERLINK("#Mis Módulos!A1","📚 Módulos") -> 📚 Módulos | E5: =HYPERLINK("#Biblioteca!A1","📖 Biblioteca") -> 📖 Biblioteca | F5: 📅 Calendario | G5: =HYPERLINK("#Hoy!A1","☀️ Hoy") -> ☀️ Hoy | H5: =HYPERLINK("#Dashboard Global!A1","📊 Dashboard+") -> 📊 Dashboard+
B8: CALENDARIO DE EVENTOS ACADÉMICOS — introduce las fechas manualmente
B9: Módulo | C9: Fecha inicio | D9: Fecha fin | E9: Evaluación | F9: Descripción | G9: Grupo | H9: Tipo | I9: Estado
B70: ★ Introduce los eventos del curso: exámenes, entregas de proyectos y recuperaciones. Usa Ctrl+F para buscar por módulo o grupo.

Sheet Hoy
B2: ☀️ Panel Diario — Hoy
B3: Pendientes · Próximos exámenes · Alumnos en riesgo · Tutorías
B5: =HYPERLINK("#Inicio!A1","🏠 Inicio") -> 🏠 Inicio | C5: =HYPERLINK("#Configuración!A1","⚙️ Config") -> ⚙️ Config | D5: =HYPERLINK("#Mis Módulos!A1","📚 Módulos") -> 📚 Módulos | E5: =HYPERLINK("#Biblioteca!A1","📖 Biblioteca") -> 📖 Biblioteca | F5: =HYPERLINK("#Calendario!A1","📅 Calendario") -> 📅 Calendario | G5: ☀️ Hoy | H5: =HYPERLINK("#Dashboard Global!A1","📊 Dashboard+") -> 📊 Dashboard+
B8: =TEXT(TODAY(),"DDDD, D DE MMMM DE YYYY") -> #VALUE! | E8: Curso académico 2026-2027
B10: MIS MÓDULOS HOY
B11: Módulo | C11: Nombre completo | D11: Grupo | E11: Horas/sem | F11: Próx. examen | G11: Estado eval
B12: =HYPERLINK("#ISO · Dashboard!A1","ISO") -> ISO | C12: Implantación de Sistemas Operativos | D12: 1º ASIR-A | E12: 6 h/sem | F12: → ver Calendario | G12: En curso
B13: =HYPERLINK("#PAR · Dashboard!A1","PAR") -> PAR | C13: Planificación y Administración de Redes | D13: 1º ASIR-A | E13: 5 h/sem | F13: → ver Calendario | G13: En curso
B15: ⚠️ ALUMNOS EN RIESGO — KPIs por módulo (desde Dashboard)
B16: Módulo | C16: Grupo | D16: Activos | E16: Aptos | F16: No Aptos | G16: En Riesgo (<4)
B17: ISO | C17: 1º ASIR-A | D17: =IFERROR(COUNTA('ISO · Alumnos'!C10:C39),"") -> 0 | E17: =IFERROR('ISO · Dashboard'!E10,"–") -> 0 | F17: =IFERROR('ISO · Dashboard'!G10,"–") -> 0 | G17: =IFERROR('ISO · Dashboard'!I10,"–") -> 0
B18: PAR | C18: 1º ASIR-A | D18: =IFERROR(COUNTA('PAR · Alumnos'!C10:C39),"") -> 0 | E18: =IFERROR('PAR · Dashboard'!E10,"–") -> 0 | F18: =IFERROR('PAR · Dashboard'!G10,"–") -> 0 | G18: =IFERROR('PAR · Dashboard'!I10,"–") -> 0
B20: 📝 NOTAS RÁPIDAS DEL DÍA — borra y reescribe cada jornada
B29: ★ El bloque 'En Riesgo' lee los KPIs directamente desde el Dashboard de cada módulo.

Sheet Dashboard Global
B2: 📊 Dashboard Global — Curso Completo
B3: Estadísticas consolidadas por módulo y grupo · Curso 2026-2027
B5: =HYPERLINK("#Inicio!A1","🏠 Inicio") -> 🏠 Inicio | C5: =HYPERLINK("#Configuración!A1","⚙️ Config") -> ⚙️ Config | D5: =HYPERLINK("#Mis Módulos!A1","📚 Módulos") -> 📚 Módulos | E5: =HYPERLINK("#Biblioteca!A1","📖 Biblioteca") -> 📖 Biblioteca | F5: =HYPERLINK("#Calendario!A1","📅 Calendario") -> 📅 Calendario | G5: =HYPERLINK("#Hoy!A1","☀️ Hoy") -> ☀️ Hoy | H5: 📊 Dashboard+
B8: RESUMEN POR MÓDULO — datos en tiempo real desde cada Dashboard
B9: Módulo | C9: Nombre | D9: Activos | E9: ✅ Aptos | F9: ❌ No Aptos | G9: ⚠️ En Riesgo | H9: Media grupo | I9: % Aprobados
B10: =HYPERLINK("#ISO · Dashboard!A1","ISO") -> ISO | C10: Implantación de Sistemas Operativos | D10: =IFERROR(COUNTA('ISO · Alumnos'!C10:C39),"") -> 0 | E10: =IFERROR(COUNTIF('ISO · 1ªORD'!M11:M40,"APTO"),"") -> 0 | F10: =IFERROR(COUNTIF('ISO · 1ªORD'!M11:M40,"NO APTO"),"") -> 0 | G10: =IFERROR(COUNTIFS('ISO · 1ªORD'!L11:L40,">0",'ISO · 1ªORD'!L11:L40,"<4"),"") -> 0 | H10: =IFERROR(ROUND(AVERAGE('ISO · 1ªORD'!L11:L40),2),"") | I10: =IFERROR(TEXT(COUNTIF('ISO · 1ªORD'!M11:M40,"APTO")/COUNTA('ISO · 1ªORD'!M11:M40),"0%"),"") -> 0%
B11: =HYPERLINK("#PAR · Dashboard!A1","PAR") -> PAR | C11: Planificación y Administración de Rede | D11: =IFERROR(COUNTA('PAR · Alumnos'!C10:C39),"") -> 0 | E11: =IFERROR(COUNTIF('PAR · 1ªORD'!K11:K40,"APTO"),"") -> 0 | F11: =IFERROR(COUNTIF('PAR · 1ªORD'!K11:K40,"NO APTO"),"") -> 0 | G11: =IFERROR(COUNTIFS('PAR · 1ªORD'!J11:J40,">0",'PAR · 1ªORD'!J11:J40,"<4"),"") -> 0 | H11: =IFERROR(ROUND(AVERAGE('PAR · 1ªORD'!J11:J40),2),"") | I11: =IFERROR(TEXT(COUNTIF('PAR · 1ªORD'!K11:K40,"APTO")/COUNTA('PAR · 1ªORD'!K11:K40),"0%"),"") -> 0%
B12: TOTAL CURSO | D12: =SUM(D10:D11) -> 0 | E12: =SUM(E10:E11) -> 0 | F12: =SUM(F10:F11) -> 0 | G12: =SUM(G10:G11) -> 0 | H12: =IFERROR(ROUND(AVERAGE(H10:H11),2),"") | I12: =IFERROR(TEXT(E11/D11,"0%"),"")
B14: ACCESOS RÁPIDOS — Dashboards por módulo
B15: ISO — 1º ASIR-A | C15: =HYPERLINK("#ISO · Dashboard!A1","📊 Dashboard ISO") -> 📊 Dashboard ISO | E15: =HYPERLINK("#ISO · Programación!A1","📋 Programación ISO") -> 📋 Programación ISO | G15: =HYPERLINK("#ISO · Informe Grupo!A1","📄 Inf.Grupo ISO") -> 📄 Inf.Grupo ISO
B16: PAR — 1º ASIR-A | C16: =HYPERLINK("#PAR · Dashboard!A1","📊 Dashboard PAR") -> 📊 Dashboard PAR | E16: =HYPERLINK("#PAR · Programación!A1","📋 Programación PAR") -> 📋 Programación PAR | G16: =HYPERLINK("#PAR · Informe Grupo!A1","📄 Inf.Grupo PAR") -> 📄 Inf.Grupo PAR
B18: ★ Todos los indicadores se calculan automáticamente desde las hojas 1ªORD y Alumnos de cada módulo.

Sheet _IA_Config
A1: EvalFP — Asistente IA (Sprint 2.6)
A2: Generación de contenido pedagógico asistido por IA
A3: ────────────────────────────────────────────────────────────
A5: ¿Qué genera? | B5: Descriptores de rúbrica · Propuestas de actividades · Informes individuales
A6: Script | B6: scripts/ai_asistente.py
A7: Dependencia | B7: pip install anthropic (o pip install openai)
A8: API Key (Claude) | B8: Configura la variable de entorno: ANTHROPIC_API_KEY=sk-ant-...
A9: API Key (OpenAI) | B9: Configura la variable de entorno: OPENAI_API_KEY=sk-...
A10: Sin API Key | B10: Funciona en modo DEMO con texto de ejemplo (sin llamada a API)
A12: Comandos de ejemplo
B13: python scripts/ai_asistente.py --ayuda
B14: # Módulo ISO
B15: python scripts/ai_asistente.py rubrica --modulo iso_data --ra RA1
B16: python scripts/ai_asistente.py actividad --modulo iso_data --ra RA2 --n 3
B17: python scripts/ai_asistente.py todo --modulo iso_data --salida ia_output/iso
B18: # Módulo PAR
B19: python scripts/ai_asistente.py rubrica --modulo par_data --ra RA1
B20: python scripts/ai_asistente.py actividad --modulo par_data --ra RA2 --n 3
B21: python scripts/ai_asistente.py todo --modulo par_data --salida ia_output/par
A23: Generación completa
B24: python scripts/build_template.py --ia # genera xlsx + contenido IA
A26: Módulos configurados: ISO, PAR

Sheet ISO · Programación
B2: 📋 Programación Didáctica — ISO 1º ASIR
B3: Distribución de RAs y CEs por Unidad de Trabajo · Implantación de Sistemas Operativos · 2026-2027
B5: =HYPERLINK("#Mis Módulos!A1","← Módulos") -> ← Módulos | C5: 📋 Programa | D5: =HYPERLINK("#ISO · Alumnos!A1","👥 Alumnos") -> 👥 Alumnos | E5: =HYPERLINK("#ISO · Actividades!A1","📝 Actividades") -> 📝 Actividades | F5: =HYPERLINK("#ISO · Reg. Notas!A1","📊 Reg. Notas") -> 📊 Reg. Notas | G5: =HYPERLINK("#ISO · Resumen!A1","📈 Resumen") -> 📈 Resumen | H5: =HYPERLINK("#ISO · Evaluación 1!A1","Eval 1") -> Eval 1 | I5: =HYPERLINK("#ISO · Evaluación 2!A1","Eval 2") -> Eval 2 | J5: =HYPERLINK("#ISO · Evaluación 3!A1","Eval 3") -> Eval 3 | K5: =HYPERLINK("#ISO · 1ªORD!A1","1ª ORD") -> 1ª ORD | L5: =HYPERLINK("#ISO · 2ªORD!A1","2ª ORD") -> 2ª ORD | M5: =HYPERLINK("#ISO · Rúbricas!A1","🎯 Rúbricas") -> 🎯 Rúbricas | N5: =HYPERLINK("#ISO · Informe Grupo!A1","📊 Inf.Grupo") -> 📊 Inf.Grupo | O5: =HYPERLINK("#ISO · Boletín!A1","📄 Boletín") -> 📄 Boletín | P5: =HYPERLINK("#ISO · Dashboard!A1","📊 Dashboard") -> 📊 Dashboard
B8: MAPA DE UNIDADES DE TRABAJO · RESULTADOS DE APRENDIZAJE · CRITERIOS DE EVALUACIÓN
B9: Eval. | C9: UT | D9: Unidad de Trabajo | E9: Horas | F9: % Total | G9: RA | H9: Criterios de Evaluación (CEs) | I9: N.º CEs | J9: % RA en UT | K9: Horas RA en UT | L9: % Pond. Global RA | M9: Instrumento(s) | N9: 📖 Apuntes
B10: EV1 | C10: UT1 | D10: Instalación de software libre y propietario | E10: 30 | F10: 16.1% | G10: RA1 | H10: CR1 CR2 CR3 CR4 CR5 CR6 CR7 CR8 | I10: 8 | J10: 80.0% | K10: 24 | L10: 13% | M10: 📝 Examen · 🔧 Práctica | N10: =HYPERLINK("../apuntes/04-FP/ISO/1-asir/instalacion-de-software-libre-y-propietario/index.html","📖 Ver apunte") -> 📖 Ver apunte
G11: RA2 | H11: CR7 CR8 | I11: 2 | J11: 20.0% | K11: 6 | L11: 19% | M11: 📝 Examen · 🔧 Práctica
B13: EV1 | C13: UT2 | D13: Administración de software base | E13: 25 | F13: 13.4% | G13: RA2 | H13: CR1 CR2 CR3 CR4 CR5 CR6 CR10 CR11 CR12 CR13 CR14 CR16 CR17 CR19 | I13: 14 | J13: 93.3% | K13: 23.3 | L13: 19% | M13: 📝 Examen · 🔧 Práctica | N13: =HYPERLINK("../apuntes/04-FP/ISO/1-asir/administracion-de-software-base/index.html","📖 Ver apunte") -> 📖 Ver apunte
G14: RA7 | H14: CR1 | I14: 1 | J14: 6.7% | K14: 1.7 | L14: 13% | M14: 📝 Examen · 🔧 Práctica
B16: EV2 | C16: UT3 | D16: Administración y aseguramiento de la información | E16: 22 | F16: 11.8% | G16: RA3 | H16: CR1 CR2 CR3 CR4 CR5 CR6 CR7 CR8 | I16: 8 | J16: 72.7% | K16: 16 | L16: 9% | M16: 📝 Examen · 🔧 Práctica | N16: =HYPERLINK("../apuntes/04-FP/ISO/1-asir/administracion-y-aseguramiento-de-la-informacion/index.html","📖 Ver apunte") -> 📖 Ver apunte
G17: RA2 | H17: CR9 CR15 CR18 | I17: 3 | J17: 27.3% | K17: 6 | L17: 19% | M17: 📝 Examen · 🔧 Práctica
B19: EV2 | C19: UT4 | D19: Gestión de dominios | E19: 30 | F19: 16.1% | G19: RA4 | H19: CR1 CR2 CR3 CR4 CR5 CR6 CR7 CR8 | I19: 8 | J19: 100.0% | K19: 30 | L19: 16% | M19: 📝 Examen · 🔧 Práctica | N19: =HYPERLINK("../apuntes/04-FP/ISO/1-asir/gestion-de-dominios/index.html","📖 Ver apunte") -> 📖 Ver apunte
B21: EV2 | C21: UT5 | D21: Administración de acceso al dominio | E21: 25 | F21: 13.4% | G21: RA5 | H21: CR1 CR2 CR3 CR4 CR5 CR6 CR7 | I21: 7 | J21: 87.5% | K21: 21.9 | L21: 13% | M21: 📝 Examen · 🔧 Práctica | N21: =HYPERLINK("../apuntes/04-FP/ISO/1-asir/administracion-de-acceso-al-dominio/index.html","📖 Ver apunte") -> 📖 Ver apunte
G22: RA7 | H22: CR1 | I22: 1 | J22: 12.5% | K22: 3.1 | L22: 13% | M22: 📝 Examen · 🔧 Práctica
B24: EV3 | C24: UT6 | D24: Supervisión del rendimiento del sistema | E24: 22 | F24: 11.8% | G24: RA6 | H24: CR1 CR2 CR3 CR4 CR5 CR6 CR7 CR8 CR9 CR10 | I24: 10 | J24: 100.0% | K24: 22 | L24: 12% | M24: 📝 Examen · 🔧 Práctica | N24: =HYPERLINK("../apuntes/04-FP/ISO/1-asir/supervision-del-rendimiento-del-sistema/index.html","📖 Ver apunte") -> 📖 Ver apunte
B26: EV3 | C26: UT7 | D26: Directivas de seguridad y auditorías | E26: 22 | F26: 11.8% | G26: RA7 | H26: CR1 CR2 CR3 CR4 CR5 CR6 CR7 CR8 CR9 | I26: 9 | J26: 90.0% | K26: 19.8 | L26: 13% | M26: 📝 Examen · 🔧 Práctica | N26: =HYPERLINK("../apuntes/04-FP/ISO/1-asir/directivas-de-seguridad-y-auditorias/index.html","📖 Ver apunte") -> 📖 Ver apunte
G27: RA5 | H27: CR8 | I27: 1 | J27: 10.0% | K27: 2.2 | L27: 13% | M27: 📝 Examen · 🔧 Práctica
B29: EV3 | C29: UT8 | D29: Resolución de incidencias y asistencia técnica | E29: 10 | F29: 5.4% | G29: 🏢 RA8 | H29: CR1 CR2 CR3 CR4 CR5 CR6 CR7 CR8 CR9 | I29: 9 | J29: 100.0% | K29: 10 | L29: 5% | M29: 🏢 Empresa | N29: =HYPERLINK("../apuntes/04-FP/ISO/1-asir/resolucion-de-incidencias-y-asistencia-tecnica/index.html","📖 Ver apunte") -> 📖 Ver apunte
B32: RESUMEN DE RESULTADOS DE APRENDIZAJE — PONDERACIÓN TOTAL DEL MÓDULO
B33: Eval. | C33: RA | D33: Resultado de Aprendizaje | E33: Total CEs | F33: Horas equiv. | G33: Ponderación % | H33: Instrumento(s)
B34: EV1 | C34: RA1 | D34: Instala sistemas operativos, relacionando sus características con el hardware del equipo y el software de aplicación. | E34: 8 | F34: 24.0 h | G34: 13% | H34: 📝 Examen · 🔧 Práctica
B35: EV1 | C35: RA2 | D35: Gestiona el software de base, aplicando criterios de explotación del sistema. | E35: 19 | F35: 35.3 h | G35: 19% | H35: 📝 Examen · 🔧 Práctica
B36: EV2 | C36: RA3 | D36: Asegura y recupera el sistema, aplicando procedimientos de administración de la información. | E36: 8 | F36: 16.0 h | G36: 9% | H36: 📝 Examen · 🔧 Práctica
B37: EV2 | C37: RA4 | D37: Gestiona dominios, elaborando el modelo lógico de la red en un entorno de trabajo. | E37: 8 | F37: 30.0 h | G37: 16% | H37: 📝 Examen · 🔧 Práctica
B38: EV2 | C38: RA5 | D38: Administra el acceso al dominio, gestionando servidores de directorio y verificando el acceso de los usuarios. | E38: 8 | F38: 24.1 h | G38: 13% | H38: 📝 Examen · 🔧 Práctica
B39: EV3 | C39: RA6 | D39: Supervisa el rendimiento del sistema, diagnosticando las causas de pérdidas de rendimiento. | E39: 10 | F39: 22.0 h | G39: 12% | H39: 📝 Examen · 🔧 Práctica
B40: EV3 | C40: RA7 | D40: Aplica directivas de seguridad y gestiona auditorías, interpretando y aplicando la normativa vigente. | E40: 9 | F40: 24.6 h | G40: 13% | H40: 📝 Examen · 🔧 Práctica
B41: EV3 | C41: 🏢 RA8 | D41: Establece la conexión en red de los sistemas informáticos, configurando dispositivos y protocolos. | E41: 9 | F41: 10.0 h | G41: 5% | H41: 🏢 Empresa
B42: TOTAL — 8 Resultados de Aprendizaje | E42: 79 | F42: 186 h | G42: 100%
B44: 🏢 EVALUACIÓN DUAL — Justificación
B45: RA8 — Resolución de incidencias y asistencia técnica — se evalúa en modalidad DUAL de acuerdo con el artículo 42 de la Ley Orgánica 3/2022 de ordenación e integración de la FP, que obliga a dualizar un mínimo del 10% de los Resultados de Aprendizaje. Se ha seleccionado este RA por ser el de mayor aplicabilidad en entorno laboral real (gestión de incidencias ITIL, WDS/MDT, VPN, acceso remoto), el de menor peso ponderado (5% = 0,05 de la nota final) y el que más naturalmente puede ser evaluado por un tutor de empresa sin necesidad de instrumentos técnicos específicos del centro. La calificación la otorga el tutor/a de empresa y se incorpora directamente a la columna RA8 de la hoja 1ªORD. NOTA IMPORTANTE: En el caso de que este RA no llegue a impartirse en el centro educativo por falta de tiempo lectivo, la evaluación recae íntegramente (100%) en el tutor/a de empresa. Esta circunstancia está prevista y amparada por la modalidad dual: el alumno/a adquiere y demuestra los contenidos de este RA exclusivamente en el entorno de trabajo, y la calificación del tutor/a de empresa es la única que computa para este RA. El peso en la nota final del módulo sigue siendo el mismo: 5% (0,05).
B46: Peso del RA dual en la nota final: 5% = 0.05 puntos sobre 1 | Evaluador: Tutor/a de empresa | Base legal: Ley Orgánica 3/2022, art. 42

Sheet ISO · Alumnos
B2: 👥 Lista de Alumnos
B3: Registro de alumnado del grupo — datos académicos y de contacto
B5: =HYPERLINK("#Mis Módulos!A1","← Módulos") -> ← Módulos | C5: =HYPERLINK("#ISO · Programación!A1","📋 Programa") -> 📋 Programa | D5: 👥 Alumnos | E5: =HYPERLINK("#ISO · Actividades!A1","📝 Actividades") -> 📝 Actividades | F5: =HYPERLINK("#ISO · Reg. Notas!A1","📊 Reg. Notas") -> 📊 Reg. Notas | G5: =HYPERLINK("#ISO · Resumen!A1","📈 Resumen") -> 📈 Resumen | H5: =HYPERLINK("#ISO · Evaluación 1!A1","Eval 1") -> Eval 1 | I5: =HYPERLINK("#ISO · Evaluación 2!A1","Eval 2") -> Eval 2 | J5: =HYPERLINK("#ISO · Evaluación 3!A1","Eval 3") -> Eval 3 | K5: =HYPERLINK("#ISO · 1ªORD!A1","1ª ORD") -> 1ª ORD | L5: =HYPERLINK("#ISO · 2ªORD!A1","2ª ORD") -> 2ª ORD | M5: =HYPERLINK("#ISO · Rúbricas!A1","🎯 Rúbricas") -> 🎯 Rúbricas | N5: =HYPERLINK("#ISO · Informe Grupo!A1","📊 Inf.Grupo") -> 📊 Inf.Grupo | O5: =HYPERLINK("#ISO · Boletín!A1","📄 Boletín") -> 📄 Boletín | P5: =HYPERLINK("#ISO · Dashboard!A1","📊 Dashboard") -> 📊 Dashboard
B8: Total activos: | C8: =COUNTIF(J9:J38,"Activo") -> 29 | D8: Bajas: | E8: =COUNTIF(J9:J38,"Baja") -> 0 | F8: Pendientes: | G8: =COUNTIF(J9:J38,"Pendiente") -> 0
B9: Nº | C9: Apellidos | D9: Nombre | E9: NIA / Exp. | F9: Fecha nacim. | G9: Email | H9: Teléfono contacto | I9: Observaciones | J9: Estado
B10: 1 | J10: Activo
B11: 2 | J11: Activo
B12: 3 | J12: Activo
B13: 4 | J13: Activo
B14: 5 | J14: Activo
B15: 6 | J15: Activo
B16: 7 | J16: Activo
B17: 8 | J17: Activo
B18: 9 | J18: Activo
B19: 10 | J19: Activo
B20: 11 | J20: Activo
B21: 12 | J21: Activo
... B39: 30 | J39: Activo

Sheet ISO · Actividades
B2: 📝 Actividades Evaluables — ISO 1º ASIR
B3: Prácticas y exámenes vinculados a RAs y CEs · Implantación de Sistemas Operativos · 2026-2027
B5: =HYPERLINK("#Mis Módulos!A1","← Módulos") -> ← Módulos | C5: =HYPERLINK("#ISO · Programación!A1","📋 Programa") -> 📋 Programa | D5: =HYPERLINK("#ISO · Alumnos!A1","👥 Alumnos") -> 👥 Alumnos | E5: 📝 Actividades | F5: =HYPERLINK("#ISO · Reg. Notas!A1","📊 Reg. Notas") -> 📊 Reg. Notas | G5: =HYPERLINK("#ISO · Resumen!A1","📈 Resumen") -> 📈 Resumen | H5: =HYPERLINK("#ISO · Evaluación 1!A1","Eval 1") -> Eval 1 | I5: =HYPERLINK("#ISO · Evaluación 2!A1","Eval 2") -> Eval 2 | J5: =HYPERLINK("#ISO · Evaluación 3!A1","Eval 3") -> Eval 3 | K5: =HYPERLINK("#ISO · 1ªORD!A1","1ª ORD") -> 1ª ORD | L5: =HYPERLINK("#ISO · 2ªORD!A1","2ª ORD") -> 2ª ORD | M5: =HYPERLINK("#ISO · Rúbricas!A1","🎯 Rúbricas") -> 🎯 Rúbricas | N5: =HYPERLINK("#ISO · Informe Grupo!A1","📊 Inf.Grupo") -> 📊 Inf.Grupo | O5: =HYPERLINK("#ISO · Boletín!A1","📄 Boletín") -> 📄 Boletín | P5: =HYPERLINK("#ISO · Dashboard!A1","📊 Dashboard") -> 📊 Dashboard
B8: ℹ️ Las actividades prácticas se han generado automáticamente desde la Programación. Ajusta la descripción, el tipo y el peso según tu planificación.
B9: ID | C9: Eval. | D9: UT | E9: RA | F9: CEs vinculados | G9: Descripción de la actividad | H9: Instrumento | I9: Tipo | J9: Peso (%) | K9: Nota máx.
B10: A001 | C10: EV1 | D10: UT1 | E10: RA1 | F10: CR1 CR2 CR3 CR4 CR5 CR6 CR7 CR8 | G10: Instalación de software libre y propietario — práctica RA1 | H10: 🔧 Práctica | I10: Individual | K10: 10
B11: A002 | C11: EV1 | D11: UT1 | E11: RA2 | F11: CR7 CR8 | G11: Instalación de software libre y propietario — práctica RA2 | H11: 🔧 Práctica | I11: Individual | K11: 10
B12: A003 | C12: EV1 | D12: UT2 | E12: RA2 | F12: CR1 CR2 CR3 CR4 CR5 CR6 CR10 CR11 … (+6) | G12: Administración de software base — práctica RA2 | H12: 🔧 Práctica | I12: Individual | K12: 10
B13: A004 | C13: EV2 | D13: UT3 | E13: RA3 | F13: CR1 CR2 CR3 CR4 CR5 CR6 CR7 CR8 | G13: Administración y aseguramiento de la información — práctica RA3 | H13: 🔧 Práctica | I13: Individual | K13: 10
B14: A005 | C14: EV2 | D14: UT4 | E14: RA4 | F14: CR1 CR2 CR3 CR4 CR5 CR6 CR7 CR8 | G14: Gestión de dominios — práctica RA4 | H14: 🔧 Práctica | I14: Individual | K14: 10
B15: A006 | C15: EV2 | D15: UT5 | E15: RA5 | F15: CR1 CR2 CR3 CR4 CR5 CR6 CR7 | G15: Administración de acceso al dominio — práctica RA5 | H15: 🔧 Práctica | I15: Individual | K15: 10
B16: A007 | C16: EV3 | D16: UT6 | E16: RA6 | F16: CR1 CR2 CR3 CR4 CR5 CR6 CR7 CR8 … (+2) | G16: Supervisión del rendimiento del sistema — práctica RA6 | H16: 🔧 Práctica | I16: Individual | K16: 10
B17: A008 | C17: EV3 | D17: UT7 | E17: RA7 | F17: CR1 CR2 CR3 CR4 CR5 CR6 CR7 CR8 … (+1) | G17: Directivas de seguridad y auditorías — práctica RA7 | H17: 🔧 Práctica | I17: Individual | K17: 10
B18: A009 | C18: EV3 | D18: UT8 | E18: RA8 | F18: CR1 CR2 CR3 CR4 CR5 CR6 CR7 CR8 … (+1) | G18: Resolución de incidencias y asistencia técnica — práctica RA8 | H18: 🔧 Práctica | I18: Individual | K18: 10
B20: EX1 | C20: EV1 | D20: UT1+UT2 | E20: RA1+RA2 | F20: Todos los CEs de la evaluación | G20: Examen teórico-práctico Evaluación 1 | H20: 📝 Examen | I20: Individual | K20: 10
B21: EX2 | C21: EV2 | D21: UT3+UT4+UT5 | E21: RA3+RA4+RA5 | F21: Todos los CEs de la evaluación | G21: Examen teórico-práctico Evaluación 2 | H21: 📝 Examen | I21: Individual | K21: 10
B22: EX3 | C22: EV3 | D22: UT6+UT7+UT8 | E22: RA6+RA7+RA8 | F22: Todos los CEs de la evaluación | G22: Examen teórico-práctico Evaluación 3 | H22: 📝 Examen | I22: Individual | K22: 10
B24: 💡 Peso (%): indica el porcentaje de la nota de prácticas que pondera esta actividad para cada RA. Los exámenes tienen su propio peso (configurable en Configuración → Peso examen). La suma de pesos de prácticas por RA debería ser 100%.

Sheet ISO · Reg. Notas
B2: 📊 Registro de Notas
B3: Calificaciones por alumno/a · Actividades, Exámenes y RAs · ISO 1º ASIR · 2026-2027
B5: =HYPERLINK("#Mis Módulos!A1","← Módulos") -> ← Módulos | C5: =HYPERLINK("#ISO · Programación!A1","📋 Programa") -> 📋 Programa | D5: =HYPERLINK("#ISO · Alumnos!A1","👥 Alumnos") -> 👥 Alumnos | E5: =HYPERLINK("#ISO · Actividades!A1","📝 Actividades") -> 📝 Actividades | F5: 📊 Reg. Notas | G5: =HYPERLINK("#ISO · Resumen!A1","📈 Resumen") -> 📈 Resumen | H5: =HYPERLINK("#ISO · Evaluación 1!A1","Eval 1") -> Eval 1 | I5: =HYPERLINK("#ISO · Evaluación 2!A1","Eval 2") -> Eval 2 | J5: =HYPERLINK("#ISO · Evaluación 3!A1","Eval 3") -> Eval 3 | K5: =HYPERLINK("#ISO · 1ªORD!A1","1ª ORD") -> 1ª ORD | L5: =HYPERLINK("#ISO · 2ªORD!A1","2ª ORD") -> 2ª ORD | M5: =HYPERLINK("#ISO · Rúbricas!A1","🎯 Rúbricas") -> 🎯 Rúbricas | N5: =HYPERLINK("#ISO · Informe Grupo!A1","📊 Inf.Grupo") -> 📊 Inf.Grupo | O5: =HYPERLINK("#ISO · Boletín!A1","📄 Boletín") -> 📄 Boletín | P5: =HYPERLINK("#ISO · Dashboard!A1","📊 Dashboard") -> 📊 Dashboard
B8: ℹ️ Introduzca las calificaciones de actividades (prácticas) y exámenes. Nota RA = % examen + % prácticas (configurables en la hoja Configuración). Las columnas de RAs y la nota final se calculan automáticamente.
D9: ACTIVIDADES (PRÁCTICAS) | M9: EXÁMENES (TEORÍA) | P9: NOTA RA (75% EX + 25% ACT) | X9: FINAL
B10: Nº | C10: Apellidos y Nombre | D10: A001 | E10: A002 | F10: A003 | G10: A004 | H10: A005 | I10: A006 | J10: A007 | K10: A008 | L10: A009 | M10: EX1 | N10: EX2 | O10: EX3 | P10: RA1 | Q10: RA2 | R10: RA3 | S10: RA4 | T10: RA5 | U10: RA6 | V10: RA7 | W10: RA8 | X10: NOTA FINAL
B11: 1 | C11: =IFERROR('ISO · Alumnos'!C10&IF('ISO · Alumnos'!D10<>"",", "&'ISO · Alumnos'!D10,""),"") | P11: =IFERROR(ROUND(PESO_EXAMEN*M11+PESO_PRACTICA*AVERAGE(D11),2),"") | Q11: =IFERROR(ROUND(PESO_EXAMEN*M11+PESO_PRACTICA*AVERAGE(E11,F11),2),"") | R11: =IFERROR(ROUND(PESO_EXAMEN*N11+PESO_PRACTICA*AVERAGE(G11),2),"") | S11: =IFERROR(ROUND(PESO_EXAMEN*N11+PESO_PRACTICA*AVERAGE(H11),2),"") | T11: =IFERROR(ROUND(PESO_EXAMEN*N11+PESO_PRACTICA*AVERAGE(I11),2),"") | U11: =IFERROR(ROUND(PESO_EXAMEN*O11+PESO_PRACTICA*AVERAGE(J11),2),"") | V11: =IFERROR(ROUND(PESO_EXAMEN*O11+PESO_PRACTICA*AVERAGE(K11),2),"") | W11: =IFERROR(ROUND(PESO_EXAMEN*O11+PESO_PRACTICA*AVERAGE(L11),2),"") | X11: =IFERROR(ROUND(P11*0.13+Q11*0.19+R11*0.09+S11*0.16+T11*0.13+U11*0.12+V11*0.13+W11*0.05,2),"")
B12: 2 | C12: =IFERROR('ISO · Alumnos'!C11&IF('ISO · Alumnos'!D11<>"",", "&'ISO · Alumnos'!D11,""),"") | P12: =IFERROR(ROUND(PESO_EXAMEN*M12+PESO_PRACTICA*AVERAGE(D12),2),"") | Q12: =IFERROR(ROUND(PESO_EXAMEN*M12+PESO_PRACTICA*AVERAGE(E12,F12),2),"") | R12: =IFERROR(ROUND(PESO_EXAMEN*N12+PESO_PRACTICA*AVERAGE(G12),2),"") | S12: =IFERROR(ROUND(PESO_EXAMEN*N12+PESO_PRACTICA*AVERAGE(H12),2),"") | T12: =IFERROR(ROUND(PESO_EXAMEN*N12+PESO_PRACTICA*AVERAGE(I12),2),"") | U12: =IFERROR(ROUND(PESO_EXAMEN*O12+PESO_PRACTICA*AVERAGE(J12),2),"") | V12: =IFERROR(ROUND(PESO_EXAMEN*O12+PESO_PRACTICA*AVERAGE(K12),2),"") | W12: =IFERROR(ROUND(PESO_EXAMEN*O12+PESO_PRACTICA*AVERAGE(L12),2),"") | X12: =IFERROR(ROUND(P12*0.13+Q12*0.19+R12*0.09+S12*0.16+T12*0.13+U12*0.12+V12*0.13+W12*0.05,2),"")
B13: 3 | C13: =IFERROR('ISO · Alumnos'!C12&IF('ISO · Alumnos'!D12<>"",", "&'ISO · Alumnos'!D12,""),"") | P13: =IFERROR(ROUND(PESO_EXAMEN*M13+PESO_PRACTICA*AVERAGE(D13),2),"") | Q13: =IFERROR(ROUND(PESO_EXAMEN*M13+PESO_PRACTICA*AVERAGE(E13,F13),2),"") | R13: =IFERROR(ROUND(PESO_EXAMEN*N13+PESO_PRACTICA*AVERAGE(G13),2),"") | S13: =IFERROR(ROUND(PESO_EXAMEN*N13+PESO_PRACTICA*AVERAGE(H13),2),"") | T13: =IFERROR(ROUND(PESO_EXAMEN*N13+PESO_PRACTICA*AVERAGE(I13),2),"") | U13: =IFERROR(ROUND(PESO_EXAMEN*O13+PESO_PRACTICA*AVERAGE(J13),2),"") | V13: =IFERROR(ROUND(PESO_EXAMEN*O13+PESO_PRACTICA*AVERAGE(K13),2),"") | W13: =IFERROR(ROUND(PESO_EXAMEN*O13+PESO_PRACTICA*AVERAGE(L13),2),"") | X13: =IFERROR(ROUND(P13*0.13+Q13*0.19+R13*0.09+S13*0.16+T13*0.13+U13*0.12+V13*0.13+W13*0.05,2),"")
B14: 4 | C14: =IFERROR('ISO · Alumnos'!C13&IF('ISO · Alumnos'!D13<>"",", "&'ISO · Alumnos'!D13,""),"") | P14: =IFERROR(ROUND(PESO_EXAMEN*M14+PESO_PRACTICA*AVERAGE(D14),2),"") | Q14: =IFERROR(ROUND(PESO_EXAMEN*M14+PESO_PRACTICA*AVERAGE(E14,F14),2),"") | R14: =IFERROR(ROUND(PESO_EXAMEN*N14+PESO_PRACTICA*AVERAGE(G14),2),"") | S14: =IFERROR(ROUND(PESO_EXAMEN*N14+PESO_PRACTICA*AVERAGE(H14),2),"") | T14: =IFERROR(ROUND(PESO_EXAMEN*N14+PESO_PRACTICA*AVERAGE(I14),2),"") | U14: =IFERROR(ROUND(PESO_EXAMEN*O14+PESO_PRACTICA*AVERAGE(J14),2),"") | V14: =IFERROR(ROUND(PESO_EXAMEN*O14+PESO_PRACTICA*AVERAGE(K14),2),"") | W14: =IFERROR(ROUND(PESO_EXAMEN*O14+PESO_PRACTICA*AVERAGE(L14),2),"") | X14: =IFERROR(ROUND(P14*0.13+Q14*0.19+R14*0.09+S14*0.16+T14*0.13+U14*0.12+V14*0.13+W14*0.05,2),"")
B15: 5 | C15: =IFERROR('ISO · Alumnos'!C14&IF('ISO · Alumnos'!D14<>"",", "&'ISO · Alumnos'!D14,""),"") | P15: =IFERROR(ROUND(PESO_EXAMEN*M15+PESO_PRACTICA*AVERAGE(D15),2),"") | Q15: =IFERROR(ROUND(PESO_EXAMEN*M15+PESO_PRACTICA*AVERAGE(E15,F15),2),"") | R15: =IFERROR(ROUND(PESO_EXAMEN*N15+PESO_PRACTICA*AVERAGE(G15),2),"") | S15: =IFERROR(ROUND(PESO_EXAMEN*N15+PESO_PRACTICA*AVERAGE(H15),2),"") | T15: =IFERROR(ROUND(PESO_EXAMEN*N15+PESO_PRACTICA*AVERAGE(I15),2),"") | U15: =IFERROR(ROUND(PESO_EXAMEN*O15+PESO_PRACTICA*AVERAGE(J15),2),"") | V15: =IFERROR(ROUND(PESO_EXAMEN*O15+PESO_PRACTICA*AVERAGE(K15),2),"") | W15: =IFERROR(ROUND(PESO_EXAMEN*O15+PESO_PRACTICA*AVERAGE(L15),2),"") | X15: =IFERROR(ROUND(P15*0.13+Q15*0.19+R15*0.09+S15*0.16+T15*0.13+U15*0.12+V15*0.13+W15*0.05,2),"")
B16: 6 | C16: =IFERROR('ISO · Alumnos'!C15&IF('ISO · Alumnos'!D15<>"",", "&'ISO · Alumnos'!D15,""),"") | P16: =IFERROR(ROUND(PESO_EXAMEN*M16+PESO_PRACTICA*AVERAGE(D16),2),"") | Q16: =IFERROR(ROUND(PESO_EXAMEN*M16+PESO_PRACTICA*AVERAGE(E16,F16),2),"") | R16: =IFERROR(ROUND(PESO_EXAMEN*N16+PESO_PRACTICA*AVERAGE(G16),2),"") | S16: =IFERROR(ROUND(PESO_EXAMEN*N16+PESO_PRACTICA*AVERAGE(H16),2),"") | T16: =IFERROR(ROUND(PESO_EXAMEN*N16+PESO_PRACTICA*AVERAGE(I16),2),"") | U16: =IFERROR(ROUND(PESO_EXAMEN*O16+PESO_PRACTICA*AVERAGE(J16),2),"") | V16: =IFERROR(ROUND(PESO_EXAMEN*O16+PESO_PRACTICA*AVERAGE(K16),2),"") | W16: =IFERROR(ROUND(PESO_EXAMEN*O16+PESO_PRACTICA*AVERAGE(L16),2),"") | X16: =IFERROR(ROUND(P16*0.13+Q16*0.19+R16*0.09+S16*0.16+T16*0.13+U16*0.12+V16*0.13+W16*0.05,2),"")
B17: 7 | C17: =IFERROR('ISO · Alumnos'!C16&IF('ISO · Alumnos'!D16<>"",", "&'ISO · Alumnos'!D16,""),"") | P17: =IFERROR(ROUND(PESO_EXAMEN*M17+PESO_PRACTICA*AVERAGE(D17),2),"") | Q17: =IFERROR(ROUND(PESO_EXAMEN*M17+PESO_PRACTICA*AVERAGE(E17,F17),2),"") | R17: =IFERROR(ROUND(PESO_EXAMEN*N17+PESO_PRACTICA*AVERAGE(G17),2),"") | S17: =IFERROR(ROUND(PESO_EXAMEN*N17+PESO_PRACTICA*AVERAGE(H17),2),"") | T17: =IFERROR(ROUND(PESO_EXAMEN*N17+PESO_PRACTICA*AVERAGE(I17),2),"") | U17: =IFERROR(ROUND(PESO_EXAMEN*O17+PESO_PRACTICA*AVERAGE(J17),2),"") | V17: =IFERROR(ROUND(PESO_EXAMEN*O17+PESO_PRACTICA*AVERAGE(K17),2),"") | W17: =IFERROR(ROUND(PESO_EXAMEN*O17+PESO_PRACTICA*AVERAGE(L17),2),"") | X17: =IFERROR(ROUND(P17*0.13+Q17*0.19+R17*0.09+S17*0.16+T17*0.13+U17*0.12+V17*0.13+W17*0.05,2),"")
B18: 8 | C18: =IFERROR('ISO · Alumnos'!C17&IF('ISO · Alumnos'!D17<>"",", "&'ISO · Alumnos'!D17,""),"") | P18: =IFERROR(ROUND(PESO_EXAMEN*M18+PESO_PRACTICA*AVERAGE(D18),2),"") | Q18: =IFERROR(ROUND(PESO_EXAMEN*M18+PESO_PRACTICA*AVERAGE(E18,F18),2),"") | R18: =IFERROR(ROUND(PESO_EXAMEN*N18+PESO_PRACTICA*AVERAGE(G18),2),"") | S18: =IFERROR(ROUND(PESO_EXAMEN*N18+PESO_PRACTICA*AVERAGE(H18),2),"") | T18: =IFERROR(ROUND(PESO_EXAMEN*N18+PESO_PRACTICA*AVERAGE(I18),2),"") | U18: =IFERROR(ROUND(PESO_EXAMEN*O18+PESO_PRACTICA*AVERAGE(J18),2),"") | V18: =IFERROR(ROUND(PESO_EXAMEN*O18+PESO_PRACTICA*AVERAGE(K18),2),"") | W18: =IFERROR(ROUND(PESO_EXAMEN*O18+PESO_PRACTICA*AVERAGE(L18),2),"") | X18: =IFERROR(ROUND(P18*0.13+Q18*0.19+R18*0.09+S18*0.16+T18*0.13+U18*0.12+V18*0.13+W18*0.05,2),"")
B19: 9 | C19: =IFERROR('ISO · Alumnos'!C18&IF('ISO · Alumnos'!D18<>"",", "&'ISO · Alumnos'!D18,""),"") | P19: =IFERROR(ROUND(PESO_EXAMEN*M19+PESO_PRACTICA*AVERAGE(D19),2),"") | Q19: =IFERROR(ROUND(PESO_EXAMEN*M19+PESO_PRACTICA*AVERAGE(E19,F19),2),"") | R19: =IFERROR(ROUND(PESO_EXAMEN*N19+PESO_PRACTICA*AVERAGE(G19),2),"") | S19: =IFERROR(ROUND(PESO_EXAMEN*N19+PESO_PRACTICA*AVERAGE(H19),2),"") | T19: =IFERROR(ROUND(PESO_EXAMEN*N19+PESO_PRACTICA*AVERAGE(I19),2),"") | U19: =IFERROR(ROUND(PESO_EXAMEN*O19+PESO_PRACTICA*AVERAGE(J19),2),"") | V19: =IFERROR(ROUND(PESO_EXAMEN*O19+PESO_PRACTICA*AVERAGE(K19),2),"") | W19: =IFERROR(ROUND(PESO_EXAMEN*O19+PESO_PRACTICA*AVERAGE(L19),2),"") | X19: =IFERROR(ROUND(P19*0.13+Q19*0.19+R19*0.09+S19*0.16+T19*0.13+U19*0.12+V19*0.13+W19*0.05,2),"")
B20: 10 | C20: =IFERROR('ISO · Alumnos'!C19&IF('ISO · Alumnos'!D19<>"",", "&'ISO · Alumnos'!D19,""),"") | P20: =IFERROR(ROUND(PESO_EXAMEN*M20+PESO_PRACTICA*AVERAGE(D20),2),"") | Q20: =IFERROR(ROUND(PESO_EXAMEN*M20+PESO_PRACTICA*AVERAGE(E20,F20),2),"") | R20: =IFERROR(ROUND(PESO_EXAMEN*N20+PESO_PRACTICA*AVERAGE(G20),2),"") | S20: =IFERROR(ROUND(PESO_EXAMEN*N20+PESO_PRACTICA*AVERAGE(H20),2),"") | T20: =IFERROR(ROUND(PESO_EXAMEN*N20+PESO_PRACTICA*AVERAGE(I20),2),"") | U20: =IFERROR(ROUND(PESO_EXAMEN*O20+PESO_PRACTICA*AVERAGE(J20),2),"") | V20: =IFERROR(ROUND(PESO_EXAMEN*O20+PESO_PRACTICA*AVERAGE(K20),2),"") | W20: =IFERROR(ROUND(PESO_EXAMEN*O20+PESO_PRACTICA*AVERAGE(L20),2),"") | X20: =IFERROR(ROUND(P20*0.13+Q20*0.19+R20*0.09+S20*0.16+T20*0.13+U20*0.12+V20*0.13+W20*0.05,2),"")
B21: 11 | C21: =IFERROR('ISO · Alumnos'!C20&IF('ISO · Alumnos'!D20<>"",", "&'ISO · Alumnos'!D20,""),"") | P21: =IFERROR(ROUND(PESO_EXAMEN*M21+PESO_PRACTICA*AVERAGE(D21),2),"") | Q21: =IFERROR(ROUND(PESO_EXAMEN*M21+PESO_PRACTICA*AVERAGE(E21,F21),2),"") | R21: =IFERROR(ROUND(PESO_EXAMEN*N21+PESO_PRACTICA*AVERAGE(G21),2),"") | S21: =IFERROR(ROUND(PESO_EXAMEN*N21+PESO_PRACTICA*AVERAGE(H21),2),"") | T21: =IFERROR(ROUND(PESO_EXAMEN*N21+PESO_PRACTICA*AVERAGE(I21),2),"") | U21: =IFERROR(ROUND(PESO_EXAMEN*O21+PESO_PRACTICA*AVERAGE(J21),2),"") | V21: =IFERROR(ROUND(PESO_EXAMEN*O21+PESO_PRACTICA*AVERAGE(K21),2),"") | W21: =IFERROR(ROUND(PESO_EXAMEN*O21+PESO_PRACTICA*AVERAGE(L21),2),"") | X21: =IFERROR(ROUND(P21*0.13+Q21*0.19+R21*0.09+S21*0.16+T21*0.13+U21*0.12+V21*0.13+W21*0.05,2),"")
B22: 12 | C22: =IFERROR('ISO · Alumnos'!C21&IF('ISO · Alumnos'!D21<>"",", "&'ISO · Alumnos'!D21,""),"") | P22: =IFERROR(ROUND(PESO_EXAMEN*M22+PESO_PRACTICA*AVERAGE(D22),2),"") | Q22: =IFERROR(ROUND(PESO_EXAMEN*M22+PESO_PRACTICA*AVERAGE(E22,F22),2),"") | R22: =IFERROR(ROUND(PESO_EXAMEN*N22+PESO_PRACTICA*AVERAGE(G22),2),"") | S22: =IFERROR(ROUND(PESO_EXAMEN*N22+PESO_PRACTICA*AVERAGE(H22),2),"") | T22: =IFERROR(ROUND(PESO_EXAMEN*N22+PESO_PRACTICA*AVERAGE(I22),2),"") | U22: =IFERROR(ROUND(PESO_EXAMEN*O22+PESO_PRACTICA*AVERAGE(J22),2),"") | V22: =IFERROR(ROUND(PESO_EXAMEN*O22+PESO_PRACTICA*AVERAGE(K22),2),"") | W22: =IFERROR(ROUND(PESO_EXAMEN*O22+PESO_PRACTICA*AVERAGE(L22),2),"") | X22: =IFERROR(ROUND(P22*0.13+Q22*0.19+R22*0.09+S22*0.16+T22*0.13+U22*0.12+V22*0.13+W22*0.05,2),"")
... B40: 30 | C40: =IFERROR('ISO · Alumnos'!C39&IF('ISO · Alumnos'!D39<>"",", "&'ISO · Alumnos'!D39,""),"") | P40: =IFERROR(ROUND(PESO_EXAMEN*M40+PESO_PRACTICA*AVERAGE(D40),2),"") | Q40: =IFERROR(ROUND(PESO_EXAMEN*M40+PESO_PRACTICA*AVERAGE(E40,F40),2),"") | R40: =IFERROR(ROUND(PESO_EXAMEN*N40+PESO_PRACTICA*AVERAGE(G40),2),"") | S40: =IFERROR(ROUND(PESO_EXAMEN*N40+PESO_PRACTICA*AVERAGE(H40),2),"") | T40: =IFERROR(ROUND(PESO_EXAMEN*N40+PESO_PRACTICA*AVERAGE(I40),2),"") | U40: =IFERROR(ROUND(PESO_EXAMEN*O40+PESO_PRACTICA*AVERAGE(J40),2),"") | V40: =IFERROR(ROUND(PESO_EXAMEN*O40+PESO_PRACTICA*AVERAGE(K40),2),"") | W40: =IFERROR(ROUND(PESO_EXAMEN*O40+PESO_PRACTICA*AVERAGE(L40),2),"") | X40: =IFERROR(ROUND(P40*0.13+Q40*0.19+R40*0.09+S40*0.16+T40*0.13+U40*0.12+V40*0.13+W40*0.05,2),"")

Sheet ISO · Resumen
B2: 📈 Resumen y Dashboard
B3: Vista general del grupo · Estadísticas y KPIs · ISO 1º ASIR · 2026-2027
B5: =HYPERLINK("#Mis Módulos!A1","← Módulos") -> ← Módulos | C5: =HYPERLINK("#ISO · Programación!A1","📋 Programa") -> 📋 Programa | D5: =HYPERLINK("#ISO · Alumnos!A1","👥 Alumnos") -> 👥 Alumnos | E5: =HYPERLINK("#ISO · Actividades!A1","📝 Actividades") -> 📝 Actividades | F5: =HYPERLINK("#ISO · Reg. Notas!A1","📊 Reg. Notas") -> 📊 Reg. Notas | G5: 📈 Resumen | H5: =HYPERLINK("#ISO · Evaluación 1!A1","Eval 1") -> Eval 1 | I5: =HYPERLINK("#ISO · Evaluación 2!A1","Eval 2") -> Eval 2 | J5: =HYPERLINK("#ISO · Evaluación 3!A1","Eval 3") -> Eval 3 | K5: =HYPERLINK("#ISO · 1ªORD!A1","1ª ORD") -> 1ª ORD | L5: =HYPERLINK("#ISO · 2ªORD!A1","2ª ORD") -> 2ª ORD | M5: =HYPERLINK("#ISO · Rúbricas!A1","🎯 Rúbricas") -> 🎯 Rúbricas | N5: =HYPERLINK("#ISO · Informe Grupo!A1","📊 Inf.Grupo") -> 📊 Inf.Grupo | O5: =HYPERLINK("#ISO · Boletín!A1","📄 Boletín") -> 📄 Boletín | P5: =HYPERLINK("#ISO · Dashboard!A1","📊 Dashboard") -> 📊 Dashboard
B8: 🚧 Este panel se completará con datos de Reg. Notas en Sprint 9 (Dashboard).
B10: 📊 Alumnos registrados
B11: ✅ Aprobados (≥5) | C11: —
B12: ❌ Suspensos (<5) | C12: —
B13: 📈 Media del grupo | C13: —
B14: ⚠️ En riesgo (<4) | C14: —

Sheet ISO · Evaluación 1
B2: 📝 Evaluación 1 · UT1, UT2
B3: RAs evaluados: RA1 40.6% · RA2 59.4% (pesos normalizados al 100% de esta evaluación)
B5: =HYPERLINK("#Mis Módulos!A1","← Módulos") -> ← Módulos | C5: =HYPERLINK("#ISO · Programación!A1","📋 Programa") -> 📋 Programa | D5: =HYPERLINK("#ISO · Alumnos!A1","👥 Alumnos") -> 👥 Alumnos | E5: =HYPERLINK("#ISO · Actividades!A1","📝 Actividades") -> 📝 Actividades | F5: =HYPERLINK("#ISO · Reg. Notas!A1","📊 Reg. Notas") -> 📊 Reg. Notas | G5: =HYPERLINK("#ISO · Resumen!A1","📈 Resumen") -> 📈 Resumen | H5: Eval 1 | I5: =HYPERLINK("#ISO · Evaluación 2!A1","Eval 2") -> Eval 2 | J5: =HYPERLINK("#ISO · Evaluación 3!A1","Eval 3") -> Eval 3 | K5: =HYPERLINK("#ISO · 1ªORD!A1","1ª ORD") -> 1ª ORD | L5: =HYPERLINK("#ISO · 2ªORD!A1","2ª ORD") -> 2ª ORD | M5: =HYPERLINK("#ISO · Rúbricas!A1","🎯 Rúbricas") -> 🎯 Rúbricas | N5: =HYPERLINK("#ISO · Informe Grupo!A1","📊 Inf.Grupo") -> 📊 Inf.Grupo | O5: =HYPERLINK("#ISO · Boletín!A1","📄 Boletín") -> 📄 Boletín | P5: =HYPERLINK("#ISO · Dashboard!A1","📊 Dashboard") -> 📊 Dashboard
F8: RA1: 13% global → 40.6% en Eval 1 | G8: RA2: 19% global → 59.4% en Eval 1
B10: Nº | C10: Apellidos y Nombre | D10: UT1 (30h) | E10: UT2 (25h) | F10: RA1 (40.6%) | G10: RA2 (59.4%) | H10: NOTA EVAL | I10: Resultado
B11: 1 | C11: =IFERROR('ISO · Alumnos'!C10&IF('ISO · Alumnos'!D10<>"",", "&'ISO · Alumnos'!D10,""),"") | F11: =IFERROR('ISO · Reg. Notas'!P11,"") | G11: =IFERROR('ISO · Reg. Notas'!Q11,"") | H11: =IFERROR(ROUND(F11*0.40625+G11*0.59375,2),"") | I11: =IF(H11="","",IF(H11>=5,"APTO","NO APTO"))
B12: 2 | C12: =IFERROR('ISO · Alumnos'!C11&IF('ISO · Alumnos'!D11<>"",", "&'ISO · Alumnos'!D11,""),"") | F12: =IFERROR('ISO · Reg. Notas'!P12,"") | G12: =IFERROR('ISO · Reg. Notas'!Q12,"") | H12: =IFERROR(ROUND(F12*0.40625+G12*0.59375,2),"") | I12: =IF(H12="","",IF(H12>=5,"APTO","NO APTO"))
B13: 3 | C13: =IFERROR('ISO · Alumnos'!C12&IF('ISO · Alumnos'!D12<>"",", "&'ISO · Alumnos'!D12,""),"") | F13: =IFERROR('ISO · Reg. Notas'!P13,"") | G13: =IFERROR('ISO · Reg. Notas'!Q13,"") | H13: =IFERROR(ROUND(F13*0.40625+G13*0.59375,2),"") | I13: =IF(H13="","",IF(H13>=5,"APTO","NO APTO"))
B14: 4 | C14: =IFERROR('ISO · Alumnos'!C13&IF('ISO · Alumnos'!D13<>"",", "&'ISO · Alumnos'!D13,""),"") | F14: =IFERROR('ISO · Reg. Notas'!P14,"") | G14: =IFERROR('ISO · Reg. Notas'!Q14,"") | H14: =IFERROR(ROUND(F14*0.40625+G14*0.59375,2),"") | I14: =IF(H14="","",IF(H14>=5,"APTO","NO APTO"))
B15: 5 | C15: =IFERROR('ISO · Alumnos'!C14&IF('ISO · Alumnos'!D14<>"",", "&'ISO · Alumnos'!D14,""),"") | F15: =IFERROR('ISO · Reg. Notas'!P15,"") | G15: =IFERROR('ISO · Reg. Notas'!Q15,"") | H15: =IFERROR(ROUND(F15*0.40625+G15*0.59375,2),"") | I15: =IF(H15="","",IF(H15>=5,"APTO","NO APTO"))
B16: 6 | C16: =IFERROR('ISO · Alumnos'!C15&IF('ISO · Alumnos'!D15<>"",", "&'ISO · Alumnos'!D15,""),"") | F16: =IFERROR('ISO · Reg. Notas'!P16,"") | G16: =IFERROR('ISO · Reg. Notas'!Q16,"") | H16: =IFERROR(ROUND(F16*0.40625+G16*0.59375,2),"") | I16: =IF(H16="","",IF(H16>=5,"APTO","NO APTO"))
B17: 7 | C17: =IFERROR('ISO · Alumnos'!C16&IF('ISO · Alumnos'!D16<>"",", "&'ISO · Alumnos'!D16,""),"") | F17: =IFERROR('ISO · Reg. Notas'!P17,"") | G17: =IFERROR('ISO · Reg. Notas'!Q17,"") | H17: =IFERROR(ROUND(F17*0.40625+G17*0.59375,2),"") | I17: =IF(H17="","",IF(H17>=5,"APTO","NO APTO"))
B18: 8 | C18: =IFERROR('ISO · Alumnos'!C17&IF('ISO · Alumnos'!D17<>"",", "&'ISO · Alumnos'!D17,""),"") | F18: =IFERROR('ISO · Reg. Notas'!P18,"") | G18: =IFERROR('ISO · Reg. Notas'!Q18,"") | H18: =IFERROR(ROUND(F18*0.40625+G18*0.59375,2),"") | I18: =IF(H18="","",IF(H18>=5,"APTO","NO APTO"))
B19: 9 | C19: =IFERROR('ISO · Alumnos'!C18&IF('ISO · Alumnos'!D18<>"",", "&'ISO · Alumnos'!D18,""),"") | F19: =IFERROR('ISO · Reg. Notas'!P19,"") | G19: =IFERROR('ISO · Reg. Notas'!Q19,"") | H19: =IFERROR(ROUND(F19*0.40625+G19*0.59375,2),"") | I19: =IF(H19="","",IF(H19>=5,"APTO","NO APTO"))
B20: 10 | C20: =IFERROR('ISO · Alumnos'!C19&IF('ISO · Alumnos'!D19<>"",", "&'ISO · Alumnos'!D19,""),"") | F20: =IFERROR('ISO · Reg. Notas'!P20,"") | G20: =IFERROR('ISO · Reg. Notas'!Q20,"") | H20: =IFERROR(ROUND(F20*0.40625+G20*0.59375,2),"") | I20: =IF(H20="","",IF(H20>=5,"APTO","NO APTO"))
B21: 11 | C21: =IFERROR('ISO · Alumnos'!C20&IF('ISO · Alumnos'!D20<>"",", "&'ISO · Alumnos'!D20,""),"") | F21: =IFERROR('ISO · Reg. Notas'!P21,"") | G21: =IFERROR('ISO · Reg. Notas'!Q21,"") | H21: =IFERROR(ROUND(F21*0.40625+G21*0.59375,2),"") | I21: =IF(H21="","",IF(H21>=5,"APTO","NO APTO"))
B22: 12 | C22: =IFERROR('ISO · Alumnos'!C21&IF('ISO · Alumnos'!D21<>"",", "&'ISO · Alumnos'!D21,""),"") | F22: =IFERROR('ISO · Reg. Notas'!P22,"") | G22: =IFERROR('ISO · Reg. Notas'!Q22,"") | H22: =IFERROR(ROUND(F22*0.40625+G22*0.59375,2),"") | I22: =IF(H22="","",IF(H22>=5,"APTO","NO APTO"))
... B40: 30 | C40: =IFERROR('ISO · Alumnos'!C39&IF('ISO · Alumnos'!D39<>"",", "&'ISO · Alumnos'!D39,""),"") | F40: =IFERROR('ISO · Reg. Notas'!P40,"") | G40: =IFERROR('ISO · Reg. Notas'!Q40,"") | H40: =IFERROR(ROUND(F40*0.40625+G40*0.59375,2),"") | I40: =IF(H40="","",IF(H40>=5,"APTO","NO APTO"))

Sheet ISO · Evaluación 2
B2: 📝 Evaluación 2 · UT3, UT4, UT5
B3: RAs evaluados: RA3 23.7% · RA4 42.1% · RA5 34.2% (pesos normalizados al 100% de esta evaluación)
B5: =HYPERLINK("#Mis Módulos!A1","← Módulos") -> ← Módulos | C5: =HYPERLINK("#ISO · Programación!A1","📋 Programa") -> 📋 Programa | D5: =HYPERLINK("#ISO · Alumnos!A1","👥 Alumnos") -> 👥 Alumnos | E5: =HYPERLINK("#ISO · Actividades!A1","📝 Actividades") -> 📝 Actividades | F5: =HYPERLINK("#ISO · Reg. Notas!A1","📊 Reg. Notas") -> 📊 Reg. Notas | G5: =HYPERLINK("#ISO · Resumen!A1","📈 Resumen") -> 📈 Resumen | H5: =HYPERLINK("#ISO · Evaluación 1!A1","Eval 1") -> Eval 1 | I5: Eval 2 | J5: =HYPERLINK("#ISO · Evaluación 3!A1","Eval 3") -> Eval 3 | K5: =HYPERLINK("#ISO · 1ªORD!A1","1ª ORD") -> 1ª ORD | L5: =HYPERLINK("#ISO · 2ªORD!A1","2ª ORD") -> 2ª ORD | M5: =HYPERLINK("#ISO · Rúbricas!A1","🎯 Rúbricas") -> 🎯 Rúbricas | N5: =HYPERLINK("#ISO · Informe Grupo!A1","📊 Inf.Grupo") -> 📊 Inf.Grupo | O5: =HYPERLINK("#ISO · Boletín!A1","📄 Boletín") -> 📄 Boletín | P5: =HYPERLINK("#ISO · Dashboard!A1","📊 Dashboard") -> 📊 Dashboard
G8: RA3: 9% global → 23.7% en Eval 2 | H8: RA4: 16% global → 42.1% en Eval 2 | I8: RA5: 13% global → 34.2% en Eval 2
B10: Nº | C10: Apellidos y Nombre | D10: UT3 (22h) | E10: UT4 (30h) | F10: UT5 (25h) | G10: RA3 (23.7%) | H10: RA4 (42.1%) | I10: RA5 (34.2%) | J10: NOTA EVAL | K10: Resultado
B11: 1 | C11: =IFERROR('ISO · Alumnos'!C10&IF('ISO · Alumnos'!D10<>"",", "&'ISO · Alumnos'!D10,""),"") | G11: =IFERROR('ISO · Reg. Notas'!R11,"") | H11: =IFERROR('ISO · Reg. Notas'!S11,"") | I11: =IFERROR('ISO · Reg. Notas'!T11,"") | J11: =IFERROR(ROUND(G11*0.236842+H11*0.421053+I11*0.342105,2),"") | K11: =IF(J11="","",IF(J11>=5,"APTO","NO APTO"))
B12: 2 | C12: =IFERROR('ISO · Alumnos'!C11&IF('ISO · Alumnos'!D11<>"",", "&'ISO · Alumnos'!D11,""),"") | G12: =IFERROR('ISO · Reg. Notas'!R12,"") | H12: =IFERROR('ISO · Reg. Notas'!S12,"") | I12: =IFERROR('ISO · Reg. Notas'!T12,"") | J12: =IFERROR(ROUND(G12*0.236842+H12*0.421053+I12*0.342105,2),"") | K12: =IF(J12="","",IF(J12>=5,"APTO","NO APTO"))
B13: 3 | C13: =IFERROR('ISO · Alumnos'!C12&IF('ISO · Alumnos'!D12<>"",", "&'ISO · Alumnos'!D12,""),"") | G13: =IFERROR('ISO · Reg. Notas'!R13,"") | H13: =IFERROR('ISO · Reg. Notas'!S13,"") | I13: =IFERROR('ISO · Reg. Notas'!T13,"") | J13: =IFERROR(ROUND(G13*0.236842+H13*0.421053+I13*0.342105,2),"") | K13: =IF(J13="","",IF(J13>=5,"APTO","NO APTO"))
B14: 4 | C14: =IFERROR('ISO · Alumnos'!C13&IF('ISO · Alumnos'!D13<>"",", "&'ISO · Alumnos'!D13,""),"") | G14: =IFERROR('ISO · Reg. Notas'!R14,"") | H14: =IFERROR('ISO · Reg. Notas'!S14,"") | I14: =IFERROR('ISO · Reg. Notas'!T14,"") | J14: =IFERROR(ROUND(G14*0.236842+H14*0.421053+I14*0.342105,2),"") | K14: =IF(J14="","",IF(J14>=5,"APTO","NO APTO"))
B15: 5 | C15: =IFERROR('ISO · Alumnos'!C14&IF('ISO · Alumnos'!D14<>"",", "&'ISO · Alumnos'!D14,""),"") | G15: =IFERROR('ISO · Reg. Notas'!R15,"") | H15: =IFERROR('ISO · Reg. Notas'!S15,"") | I15: =IFERROR('ISO · Reg. Notas'!T15,"") | J15: =IFERROR(ROUND(G15*0.236842+H15*0.421053+I15*0.342105,2),"") | K15: =IF(J15="","",IF(J15>=5,"APTO","NO APTO"))
B16: 6 | C16: =IFERROR('ISO · Alumnos'!C15&IF('ISO · Alumnos'!D15<>"",", "&'ISO · Alumnos'!D15,""),"") | G16: =IFERROR('ISO · Reg. Notas'!R16,"") | H16: =IFERROR('ISO · Reg. Notas'!S16,"") | I16: =IFERROR('ISO · Reg. Notas'!T16,"") | J16: =IFERROR(ROUND(G16*0.236842+H16*0.421053+I16*0.342105,2),"") | K16: =IF(J16="","",IF(J16>=5,"APTO","NO APTO"))
B17: 7 | C17: =IFERROR('ISO · Alumnos'!C16&IF('ISO · Alumnos'!D16<>"",", "&'ISO · Alumnos'!D16,""),"") | G17: =IFERROR('ISO · Reg. Notas'!R17,"") | H17: =IFERROR('ISO · Reg. Notas'!S17,"") | I17: =IFERROR('ISO · Reg. Notas'!T17,"") | J17: =IFERROR(ROUND(G17*0.236842+H17*0.421053+I17*0.342105,2),"") | K17: =IF(J17="","",IF(J17>=5,"APTO","NO APTO"))
B18: 8 | C18: =IFERROR('ISO · Alumnos'!C17&IF('ISO · Alumnos'!D17<>"",", "&'ISO · Alumnos'!D17,""),"") | G18: =IFERROR('ISO · Reg. Notas'!R18,"") | H18: =IFERROR('ISO · Reg. Notas'!S18,"") | I18: =IFERROR('ISO · Reg. Notas'!T18,"") | J18: =IFERROR(ROUND(G18*0.236842+H18*0.421053+I18*0.342105,2),"") | K18: =IF(J18="","",IF(J18>=5,"APTO","NO APTO"))
B19: 9 | C19: =IFERROR('ISO · Alumnos'!C18&IF('ISO · Alumnos'!D18<>"",", "&'ISO · Alumnos'!D18,""),"") | G19: =IFERROR('ISO · Reg. Notas'!R19,"") | H19: =IFERROR('ISO · Reg. Notas'!S19,"") | I19: =IFERROR('ISO · Reg. Notas'!T19,"") | J19: =IFERROR(ROUND(G19*0.236842+H19*0.421053+I19*0.342105,2),"") | K19: =IF(J19="","",IF(J19>=5,"APTO","NO APTO"))
B20: 10 | C20: =IFERROR('ISO · Alumnos'!C19&IF('ISO · Alumnos'!D19<>"",", "&'ISO · Alumnos'!D19,""),"") | G20: =IFERROR('ISO · Reg. Notas'!R20,"") | H20: =IFERROR('ISO · Reg. Notas'!S20,"") | I20: =IFERROR('ISO · Reg. Notas'!T20,"") | J20: =IFERROR(ROUND(G20*0.236842+H20*0.421053+I20*0.342105,2),"") | K20: =IF(J20="","",IF(J20>=5,"APTO","NO APTO"))
B21: 11 | C21: =IFERROR('ISO · Alumnos'!C20&IF('ISO · Alumnos'!D20<>"",", "&'ISO · Alumnos'!D20,""),"") | G21: =IFERROR('ISO · Reg. Notas'!R21,"") | H21: =IFERROR('ISO · Reg. Notas'!S21,"") | I21: =IFERROR('ISO · Reg. Notas'!T21,"") | J21: =IFERROR(ROUND(G21*0.236842+H21*0.421053+I21*0.342105,2),"") | K21: =IF(J21="","",IF(J21>=5,"APTO","NO APTO"))
B22: 12 | C22: =IFERROR('ISO · Alumnos'!C21&IF('ISO · Alumnos'!D21<>"",", "&'ISO · Alumnos'!D21,""),"") | G22: =IFERROR('ISO · Reg. Notas'!R22,"") | H22: =IFERROR('ISO · Reg. Notas'!S22,"") | I22: =IFERROR('ISO · Reg. Notas'!T22,"") | J22: =IFERROR(ROUND(G22*0.236842+H22*0.421053+I22*0.342105,2),"") | K22: =IF(J22="","",IF(J22>=5,"APTO","NO APTO"))
... B40: 30 | C40: =IFERROR('ISO · Alumnos'!C39&IF('ISO · Alumnos'!D39<>"",", "&'ISO · Alumnos'!D39,""),"") | G40: =IFERROR('ISO · Reg. Notas'!R40,"") | H40: =IFERROR('ISO · Reg. Notas'!S40,"") | I40: =IFERROR('ISO · Reg. Notas'!T40,"") | J40: =IFERROR(ROUND(G40*0.236842+H40*0.421053+I40*0.342105,2),"") | K40: =IF(J40="","",IF(J40>=5,"APTO","NO APTO"))

Sheet ISO · Evaluación 3
B2: 📝 Evaluación 3 · UT6, UT7, UT8
B3: RAs evaluados: RA6 40.0% · RA7 43.3% · RA8 16.7% (pesos normalizados al 100% de esta evaluación)
B5: =HYPERLINK("#Mis Módulos!A1","← Módulos") -> ← Módulos | C5: =HYPERLINK("#ISO · Programación!A1","📋 Programa") -> 📋 Programa | D5: =HYPERLINK("#ISO · Alumnos!A1","👥 Alumnos") -> 👥 Alumnos | E5: =HYPERLINK("#ISO · Actividades!A1","📝 Actividades") -> 📝 Actividades | F5: =HYPERLINK("#ISO · Reg. Notas!A1","📊 Reg. Notas") -> 📊 Reg. Notas | G5: =HYPERLINK("#ISO · Resumen!A1","📈 Resumen") -> 📈 Resumen | H5: =HYPERLINK("#ISO · Evaluación 1!A1","Eval 1") -> Eval 1 | I5: =HYPERLINK("#ISO · Evaluación 2!A1","Eval 2") -> Eval 2 | J5: Eval 3 | K5: =HYPERLINK("#ISO · 1ªORD!A1","1ª ORD") -> 1ª ORD | L5: =HYPERLINK("#ISO · 2ªORD!A1","2ª ORD") -> 2ª ORD | M5: =HYPERLINK("#ISO · Rúbricas!A1","🎯 Rúbricas") -> 🎯 Rúbricas | N5: =HYPERLINK("#ISO · Informe Grupo!A1","📊 Inf.Grupo") -> 📊 Inf.Grupo | O5: =HYPERLINK("#ISO · Boletín!A1","📄 Boletín") -> 📄 Boletín | P5: =HYPERLINK("#ISO · Dashboard!A1","📊 Dashboard") -> 📊 Dashboard
G8: RA6: 12% global → 40.0% en Eval 3 | H8: RA7: 13% global → 43.3% en Eval 3 | I8: RA8: 5% global → 16.7% en Eval 3
B10: Nº | C10: Apellidos y Nombre | D10: UT6 (22h) | E10: UT7 (22h) | F10: UT8 (10h) | G10: RA6 (40.0%) | H10: RA7 (43.3%) | I10: 🏢 RA8 (16.7%) EMPRESA | J10: NOTA EVAL | K10: Resultado
B11: 1 | C11: =IFERROR('ISO · Alumnos'!C10&IF('ISO · Alumnos'!D10<>"",", "&'ISO · Alumnos'!D10,""),"") | G11: =IFERROR('ISO · Reg. Notas'!U11,"") | H11: =IFERROR('ISO · Reg. Notas'!V11,"") | I11: =IFERROR('ISO · Reg. Notas'!W11,"") | J11: =IFERROR(ROUND(G11*0.4+H11*0.433333+I11*0.166667,2),"") | K11: =IF(J11="","",IF(J11>=5,"APTO","NO APTO"))
B12: 2 | C12: =IFERROR('ISO · Alumnos'!C11&IF('ISO · Alumnos'!D11<>"",", "&'ISO · Alumnos'!D11,""),"") | G12: =IFERROR('ISO · Reg. Notas'!U12,"") | H12: =IFERROR('ISO · Reg. Notas'!V12,"") | I12: =IFERROR('ISO · Reg. Notas'!W12,"") | J12: =IFERROR(ROUND(G12*0.4+H12*0.433333+I12*0.166667,2),"") | K12: =IF(J12="","",IF(J12>=5,"APTO","NO APTO"))
